Traceback (most recent call last):
  File "C:\Users\male-\AppData\Local\Programs\Python\Python313\Lib\site-packages\jupyter_cache\executors\utils.py", line 58, in single_nb_execution
    executenb(
    ~~~~~~~~~^
        nb,
        ^^^
    ...<4 lines>...
        **kwargs,
        ^^^^^^^^^
    )
    ^
  File "C:\Users\male-\AppData\Local\Programs\Python\Python313\Lib\site-packages\nbclient\client.py", line 1314, in execute
    return NotebookClient(nb=nb, resources=resources, km=km, **kwargs).execute()
           ~~~~~~~~~~~~~~~~~~~~~~~~~~~~~~~~~~~~~~~~~~~~~~~~~~~~~~~~~~~~~~~~~~~^^
  File "C:\Users\male-\AppData\Local\Programs\Python\Python313\Lib\site-packages\jupyter_core\utils\__init__.py", line 165, in wrapped
    return loop.run_until_complete(inner)
           ~~~~~~~~~~~~~~~~~~~~~~~^^^^^^^
  File "C:\Users\male-\AppData\Local\Programs\Python\Python313\Lib\asyncio\base_events.py", line 721, in run_until_complete
    return future.result()
           ~~~~~~~~~~~~~^^
  File "C:\Users\male-\AppData\Local\Programs\Python\Python313\Lib\site-packages\nbclient\client.py", line 709, in async_execute
    await self.async_execute_cell(
        cell, index, execution_count=self.code_cells_executed + 1
    )
  File "C:\Users\male-\AppData\Local\Programs\Python\Python313\Lib\site-packages\nbclient\client.py", line 1062, in async_execute_cell
    await self._check_raise_for_error(cell, cell_index, exec_reply)
  File "C:\Users\male-\AppData\Local\Programs\Python\Python313\Lib\site-packages\nbclient\client.py", line 918, in _check_raise_for_error
    raise CellExecutionError.from_cell_and_msg(cell, exec_reply_content)
nbclient.exceptions.CellExecutionError: An error occurred while executing the following cell:
------------------
from PIL import Image
img = Image.open(r"figures/30.png")
img
------------------


[1;31m---------------------------------------------------------------------------[0m
[1;31mFileNotFoundError[0m                         Traceback (most recent call last)
Cell [1;32mIn[14], line 2[0m
[0;32m      1[0m [38;5;28;01mfrom[39;00m [38;5;21;01mPIL[39;00m [38;5;28;01mimport[39;00m Image
[1;32m----> 2[0m img [38;5;241m=[39m [43mImage[49m[38;5;241;43m.[39;49m[43mopen[49m[43m([49m[38;5;124;43mr[39;49m[38;5;124;43m"[39;49m[38;5;124;43mfigures/30.png[39;49m[38;5;124;43m"[39;49m[43m)[49m
[0;32m      3[0m img

File [1;32m~\AppData\Local\Programs\Python\Python313\Lib\site-packages\PIL\Image.py:3431[0m, in [0;36mopen[1;34m(fp, mode, formats)[0m
[0;32m   3428[0m     filename [38;5;241m=[39m os[38;5;241m.[39mpath[38;5;241m.[39mrealpath(os[38;5;241m.[39mfspath(fp))
[0;32m   3430[0m [38;5;28;01mif[39;00m filename:
[1;32m-> 3431[0m     fp [38;5;241m=[39m [43mbuiltins[49m[38;5;241;43m.[39;49m[43mopen[49m[43m([49m[43mfilename[49m[43m,[49m[43m [49m[38;5;124;43m"[39;49m[38;5;124;43mrb[39;49m[38;5;124;43m"[39;49m[43m)[49m
[0;32m   3432[0m     exclusive_fp [38;5;241m=[39m [38;5;28;01mTrue[39;00m
[0;32m   3433[0m [38;5;28;01melse[39;00m:

[1;31mFileNotFoundError[0m: [Errno 2] No such file or directory: 'C:\\Users\\male-\\mynewbook\\figures\\30.png'

